<robot name="team15_robot">



<link name="world"/>



    <link name="base_link">
        <visual>
            <origin xyz="0 0 0.05" rpy="0 0 0" />
            <geometry>
                <box size="1 1 0.1" />
            </geometry>
        </visual>
        <collision>
            <geometry>
                <box size="1 1 0.07" />
            </geometry>
            <origin rpy="0 0 0" xyz="0 0 0.05" />
        </collision>
        
	<inertial>
            <mass value="1" />
            <inertia ixx="0.0" ixy="0.0" ixz="0.0" iyy="0.0" iyz="0.0" izz="0.0" />
        </inertial>

    </link>
    
    
    
    <link name="link_1">
        <visual>
            <origin xyz="0 0 0.2" rpy="0 0 0" />
            <geometry>
                <box size="0.1 0.1 0.4" />
            </geometry>
        </visual>
        <collision>
            <geometry>
                <box size="0.1 0.1 0.3" />
            </geometry>
            <origin xyz="0 0 0.2" rpy="0 0 0" />
        </collision>
        
<inertial>
            <mass value="1" />
            <inertia ixx="0.0" ixy="0.0" ixz="0.0" iyy="0.0" iyz="0.0" izz="0.0" />
        </inertial>

    </link>
    
    
    
    <link name="link_2">
        <visual>
            <origin xyz="0.2 0 0" rpy="0 0 0" />
            <geometry>
                <box size="0.4 0.08 0.08" />
            </geometry>
        </visual>
        <collision>
            <geometry>
                <box size="0.3 0.1 0.1" />
            </geometry>
            <origin xyz="0.2 0 0" rpy="0 0 0" />
        </collision>
        
<inertial>
            <mass value="0.5" />
            <inertia ixx="0.0" ixy="0.0" ixz="0.0" iyy="0.0" iyz="0.0" izz="0.0" />
        </inertial>

    </link>
    
    
    
    <link name="link_3">
        <visual>
            <origin xyz="0.15 0 0" rpy="0 0 0" />
            <geometry>
                <box size="0.3 0.07 0.07" />
            </geometry>
        </visual>
        <collision>
            <geometry>
                <box size="0.2 0.1 0.1" />
            </geometry>
            <origin xyz="0.15 0 0" rpy="0 0 0" />
        </collision>
        
<inertial>
            <mass value="0.4" />
            <inertia ixx="0.0" ixy="0.0" ixz="0.0" iyy="0.0" iyz="0.0" izz="0.0" />
        </inertial>

    </link>
    
    
    
    <link name="link_4">
        <visual>
            <origin xyz="0.1 0 0" rpy="0 0 0" />
            <geometry>
                <box size="0.2 0.06 0.06" />
            </geometry>
        </visual>
        <collision>
            <geometry>
                <box size="0.1 0.1 0.1" />
            </geometry>
            <origin xyz="0.1 0 0" rpy="0 0 0" />
        </collision>
        
<inertial>
            <mass value="0.3" />
            <inertia ixx="0.0" ixy="0.0" ixz="0.0" iyy="0.0" iyz="0.0" izz="0.0" />
        </inertial>

    </link>
    
    
    
    <link name="link_5">
        <visual>
            <origin xyz="0.1 0 0" rpy="0 0 0" />
            <geometry>
                <box size="0.2 0.05 0.05" />
            </geometry>
        </visual>
        <collision>
            <geometry>
                <box size="0.1 0.1 0.1" />
            </geometry>
            <origin xyz="0.1 0 0" rpy="0 0 0" />
        </collision>
        
<inertial>
            <mass value="0.2" />
             <inertia ixx="0.0" ixy="0.0" ixz="0.0" iyy="0.0" iyz="0.0" izz="0.0" />
        </inertial>

    </link>
    
    
    
    <link name="link_6">
        <visual>
            <origin xyz="0.1 0 0" rpy="0 0 0" />
            <geometry>
                <box size="0.2 0.04 0.04" />
            </geometry>
        </visual>
        <collision>
            <geometry>
                <box size="0.1 0.1 0.1" />
            </geometry>
            <origin xyz="0.1 0 0" rpy="0 0 0" />
        </collision>
        
<inertial>
            <mass value="0.1" />
             <inertia ixx="0.0" ixy="0.0" ixz="0.0" iyy="0.0" iyz="0.0" izz="0.0" />
        </inertial>

    </link>
    
    
    
    <link name="EF">
        <visual>
            <origin xyz="-0.05 0 0" rpy="0 0 0" />
            <geometry>
                <box size="0.1 0.02 0.02" />
            </geometry>
        </visual>
        <collision>
            <geometry>
                <box size="0.1 0.05 0.05" />
            </geometry>
            <origin xyz="-0.05 0 0" rpy="0 0 0" />
        </collision>
        
<inertial>
            <mass value="0.1" />
             <inertia ixx="0.0" ixy="0.0" ixz="0.0" iyy="0.0" iyz="0.0" izz="0.0" />
        </inertial>

    </link>
    
    
    
    
    
    
    <joint name="world_joint" type="fixed">
        <origin xyz="0 0 0" rpy="0 0 0" />
        <parent link="world" />
        <child link="base_link" />
    </joint>
    
    
    
    <joint name="joint_1" type="revolute">
        <origin xyz="0 0 0.1" rpy="0 0 0" />
        <parent link="base_link" />
        <child link="link_1" />
        <axis xyz="0 0 1" />
        <limit lower="-3.14" upper="3.14" effort="20" velocity="3" />
    </joint>
    
    
    
    <joint name="joint_2" type="revolute">
        <origin xyz="0 0 0.4" rpy="0 0 0" />
        <parent link="link_1" />
        <child link="link_2" />
        <axis xyz="0 1 0" />
        <limit lower="-3" upper="3" effort="20" velocity="3" />
    </joint>
    
    
    
    <joint name="joint_3" type="revolute">
        <origin xyz="0.4 0 0" rpy="0 0 0" />
        <parent link="link_2" />
        <child link="link_3" />
        <axis xyz="0 1 0" />
        <limit lower="-3" upper="3" effort="20" velocity="3" />
    </joint>
    
    
    
    <joint name="joint_4" type="revolute">
        <origin xyz="0.3 0 0" rpy="0 0 0" />
        <parent link="link_3" />
        <child link="link_4" />
        <axis xyz="1 0 0" />
        <limit lower="-3" upper="3" effort="20" velocity="3" />
    </joint>
    
    
    
    <joint name="joint_5" type="revolute">
        <origin xyz="0.2 0 0" rpy="0 0 0" />
        <parent link="link_4" />
        <child link="link_5" />
        <axis xyz="0 0 1" />
        <limit lower="-3" upper="3" effort="20" velocity="3" />
    </joint>
    
    
    
    <joint name="joint_6" type="revolute">
        <origin xyz="0.2 0 0" rpy="0 0 0" />
        <parent link="link_5" />
        <child link="link_6" />
        <axis xyz="1 0 0" />
        <limit lower="-3" upper="3" effort="20" velocity="3" />
    </joint>
    
    
    
    <joint name="joint_7" type="fixed">
        <origin xyz="0.3 0 0" rpy="0 0 0" />
        <parent link="link_6" />
        <child link="EF" />  
    </joint>
    
    
    
   
   
    
<transmission name="trans_joint_1">
        <type>transmission_interface/SimpleTransmission</type>
        <joint name="joint_1">
            <hardwareInterface>hardware_interface/PositionJointInterface</hardwareInterface>
        </joint>
        <actuator name="joint_1_motor">
            <hardwareInterface>hardware_interface/PositionJointInterface</hardwareInterface>
            <mechanicalReduction>1</mechanicalReduction>
        </actuator>
    </transmission>
    
    
    
    <transmission name="trans_joint_2">
        <type>transmission_interface/SimpleTransmission</type>
        <joint name="joint_2">
            <hardwareInterface>hardware_interface/PositionJointInterface</hardwareInterface>
        </joint>
        <actuator name="joint_2_motor">
            <hardwareInterface>hardware_interface/PositionJointInterface</hardwareInterface>
            <mechanicalReduction>1</mechanicalReduction>
        </actuator>
    </transmission>
    
    
    
    <transmission name="trans_joint_3">
        <type>transmission_interface/SimpleTransmission</type>
        <joint name="joint_3">
            <hardwareInterface>hardware_interface/PositionJointInterface</hardwareInterface>
        </joint>
        <actuator name="joint_3_motor">
            <hardwareInterface>hardware_interface/PositionJointInterface</hardwareInterface>
            <mechanicalReduction>1</mechanicalReduction>
        </actuator>
    </transmission>
    
    
    
    <transmission name="trans_joint_4">
        <type>transmission_interface/SimpleTransmission</type>
        <joint name="joint_4">
            <hardwareInterface>hardware_interface/PositionJointInterface</hardwareInterface>
        </joint>
        <actuator name="joint_4_motor">
            <hardwareInterface>hardware_interface/PositionJointInterface</hardwareInterface>
            <mechanicalReduction>1</mechanicalReduction>
        </actuator>
    </transmission>
    
    
    
    <transmission name="trans_joint_5">
        <type>transmission_interface/SimpleTransmission</type>
        <joint name="joint_5">
            <hardwareInterface>hardware_interface/PositionJointInterface</hardwareInterface>
        </joint>
        <actuator name="joint_5_motor">
            <hardwareInterface>hardware_interface/PositionJointInterface</hardwareInterface>
            <mechanicalReduction>1</mechanicalReduction>
        </actuator>
    </transmission>
    
    
    
    <transmission name="trans_joint_6">
        <type>transmission_interface/SimpleTransmission</type>
        <joint name="joint_6">
            <hardwareInterface>hardware_interface/PositionJointInterface</hardwareInterface>
        </joint>
        <actuator name="joint_6_motor">
            <hardwareInterface>hardware_interface/PositionJointInterface</hardwareInterface>
            <mechanicalReduction>1</mechanicalReduction>
        </actuator>
    </transmission>
    
    
    
    <gazebo>
        <plugin name="gazebo_ros_control" filename="libgazebo_ros_control.so">
            <robotNamespace>/asu_controller</robotNamespace>
            <legacyModeNS>true</legacyModeNS>
        </plugin>
    </gazebo>
    
    
    
</robot>

